Enter -['Start of 1st Half']
['Ursinus wins toss and will receive; ALV will defend North end-zone.']
['Start of 1st quarter, clock 15:00.']
['Conrad,Brett kickoff 49 yards to the URS16 Schnaars,Nick return 35 yards to the ALV49 (Scurlock,Neeko).']
Is this opponent scout? (Y/N)Are you scouting Alvernia (H) or Ursinus (A)?Final score Alvernia 27 - Ursinus 59
Folder name? (Scout team name default)Enter -['Start of 1st Half']
['JOHNS HO ball on JOHNS HO35, clock 15:00.']
["Joe Zahner kickoff 53 yards to the URSINUS12, Michael D'Amico return 18 yards to the URSINUS30 (Jack Jurkovich), out-of-bounds."]
Score correction made in Johns Hopkins @ Ursinus (index) quarter 2 drive 11
Score correction made in Johns Hopkins @ Ursinus (index) quarter 3 drive 2
Score correction made in Johns Hopkins @ Ursinus (index) quarter 3 drive 6
Is this opponent scout? (Y/N)Are you scouting Ursinus (H) or Johns Hopkins (A)?Final score Ursinus 29 - Johns Hopkins 36
Folder name? (Scout team name default)Enter -['Start of 1st Half']
['MUHL ball on MUHL35, clock 15:00.']
['Connor Fensterm kickoff 57 yards to the UC08, Nick Schnaars return 19 yards to the UC27 (Owen Daddona; John Lohrer).']
Is this opponent scout? (Y/N)Are you scouting Ursinus (H) or Muhlenberg (A)?Final score Ursinus 35 - Muhlenberg 28
Folder name? (Scout team name default)Enter -Traceback (most recent call last):
  File "C:\Program Files\WindowsApps\PythonSoftwareFoundation.Python.3.10_3.10.2032.0_x64__qbz5n2kfra8p0\lib\urllib\request.py", line 1348, in do_open
    h.request(req.get_method(), req.selector, req.data, headers,
  File "C:\Program Files\WindowsApps\PythonSoftwareFoundation.Python.3.10_3.10.2032.0_x64__qbz5n2kfra8p0\lib\http\client.py", line 1282, in request
    self._send_request(method, url, body, headers, encode_chunked)
  File "C:\Program Files\WindowsApps\PythonSoftwareFoundation.Python.3.10_3.10.2032.0_x64__qbz5n2kfra8p0\lib\http\client.py", line 1328, in _send_request
    self.endheaders(body, encode_chunked=encode_chunked)
  File "C:\Program Files\WindowsApps\PythonSoftwareFoundation.Python.3.10_3.10.2032.0_x64__qbz5n2kfra8p0\lib\http\client.py", line 1277, in endheaders
    self._send_output(message_body, encode_chunked=encode_chunked)
  File "C:\Program Files\WindowsApps\PythonSoftwareFoundation.Python.3.10_3.10.2032.0_x64__qbz5n2kfra8p0\lib\http\client.py", line 1037, in _send_output
    self.send(msg)
  File "C:\Program Files\WindowsApps\PythonSoftwareFoundation.Python.3.10_3.10.2032.0_x64__qbz5n2kfra8p0\lib\http\client.py", line 975, in send
    self.connect()
  File "C:\Program Files\WindowsApps\PythonSoftwareFoundation.Python.3.10_3.10.2032.0_x64__qbz5n2kfra8p0\lib\http\client.py", line 1447, in connect
    super().connect()
  File "C:\Program Files\WindowsApps\PythonSoftwareFoundation.Python.3.10_3.10.2032.0_x64__qbz5n2kfra8p0\lib\http\client.py", line 941, in connect
    self.sock = self._create_connection(
  File "C:\Program Files\WindowsApps\PythonSoftwareFoundation.Python.3.10_3.10.2032.0_x64__qbz5n2kfra8p0\lib\socket.py", line 824, in create_connection
    for res in getaddrinfo(host, port, 0, SOCK_STREAM):
  File "C:\Program Files\WindowsApps\PythonSoftwareFoundation.Python.3.10_3.10.2032.0_x64__qbz5n2kfra8p0\lib\socket.py", line 955, in getaddrinfo
    for res in _socket.getaddrinfo(host, port, family, type, proto, flags):
socket.gaierror: [Errno 11001] getaddrinfo failed

During handling of the above exception, another exception occurred:

Traceback (most recent call last):
  File "C:\Users\surma\Python\cfb_slapPY\sauce.py", line 12, in <module>
    quarters, name_dict = pbp_parser(url)
  File "C:\Users\surma\Python\cfb_slapPY\pbp_parser_func.py", line 15, in pbp_parser
    html = urlopen(req, context=ctx).read()
  File "C:\Program Files\WindowsApps\PythonSoftwareFoundation.Python.3.10_3.10.2032.0_x64__qbz5n2kfra8p0\lib\urllib\request.py", line 216, in urlopen
    return opener.open(url, data, timeout)
  File "C:\Program Files\WindowsApps\PythonSoftwareFoundation.Python.3.10_3.10.2032.0_x64__qbz5n2kfra8p0\lib\urllib\request.py", line 519, in open
    response = self._open(req, data)
  File "C:\Program Files\WindowsApps\PythonSoftwareFoundation.Python.3.10_3.10.2032.0_x64__qbz5n2kfra8p0\lib\urllib\request.py", line 536, in _open
    result = self._call_chain(self.handle_open, protocol, protocol +
  File "C:\Program Files\WindowsApps\PythonSoftwareFoundation.Python.3.10_3.10.2032.0_x64__qbz5n2kfra8p0\lib\urllib\request.py", line 496, in _call_chain
    result = func(*args)
  File "C:\Program Files\WindowsApps\PythonSoftwareFoundation.Python.3.10_3.10.2032.0_x64__qbz5n2kfra8p0\lib\urllib\request.py", line 1391, in https_open
    return self.do_open(http.client.HTTPSConnection, req,
  File "C:\Program Files\WindowsApps\PythonSoftwareFoundation.Python.3.10_3.10.2032.0_x64__qbz5n2kfra8p0\lib\urllib\request.py", line 1351, in do_open
    raise URLError(err)
urllib.error.URLError: <urlopen error [Errno 11001] getaddrinfo failed>

During handling of the above exception, another exception occurred:

Traceback (most recent call last):
  File "C:\Program Files\WindowsApps\PythonSoftwareFoundation.Python.3.10_3.10.2032.0_x64__qbz5n2kfra8p0\lib\urllib\request.py", line 1348, in do_open
    h.request(req.get_method(), req.selector, req.data, headers,
  File "C:\Program Files\WindowsApps\PythonSoftwareFoundation.Python.3.10_3.10.2032.0_x64__qbz5n2kfra8p0\lib\http\client.py", line 1282, in request
    self._send_request(method, url, body, headers, encode_chunked)
  File "C:\Program Files\WindowsApps\PythonSoftwareFoundation.Python.3.10_3.10.2032.0_x64__qbz5n2kfra8p0\lib\http\client.py", line 1328, in _send_request
    self.endheaders(body, encode_chunked=encode_chunked)
  File "C:\Program Files\WindowsApps\PythonSoftwareFoundation.Python.3.10_3.10.2032.0_x64__qbz5n2kfra8p0\lib\http\client.py", line 1277, in endheaders
    self._send_output(message_body, encode_chunked=encode_chunked)
  File "C:\Program Files\WindowsApps\PythonSoftwareFoundation.Python.3.10_3.10.2032.0_x64__qbz5n2kfra8p0\lib\http\client.py", line 1037, in _send_output
    self.send(msg)
  File "C:\Program Files\WindowsApps\PythonSoftwareFoundation.Python.3.10_3.10.2032.0_x64__qbz5n2kfra8p0\lib\http\client.py", line 975, in send
    self.connect()
  File "C:\Program Files\WindowsApps\PythonSoftwareFoundation.Python.3.10_3.10.2032.0_x64__qbz5n2kfra8p0\lib\http\client.py", line 1447, in connect
    super().connect()
  File "C:\Program Files\WindowsApps\PythonSoftwareFoundation.Python.3.10_3.10.2032.0_x64__qbz5n2kfra8p0\lib\http\client.py", line 941, in connect
    self.sock = self._create_connection(
  File "C:\Program Files\WindowsApps\PythonSoftwareFoundation.Python.3.10_3.10.2032.0_x64__qbz5n2kfra8p0\lib\socket.py", line 824, in create_connection
    for res in getaddrinfo(host, port, 0, SOCK_STREAM):
  File "C:\Program Files\WindowsApps\PythonSoftwareFoundation.Python.3.10_3.10.2032.0_x64__qbz5n2kfra8p0\lib\socket.py", line 955, in getaddrinfo
    for res in _socket.getaddrinfo(host, port, family, type, proto, flags):
socket.gaierror: [Errno 11001] getaddrinfo failed

During handling of the above exception, another exception occurred:

Traceback (most recent call last):
  File "C:\Users\surma\Python\cfb_slapPY\sauce.py", line 15, in <module>
    quarters, name_dict = taster(url)  
  File "C:\Users\surma\Python\cfb_slapPY\taster_func.py", line 10, in taster
    soup = pot(headers,url)
  File "C:\Users\surma\Python\cfb_slapPY\presto_prep.py", line 9, in pot
    response = urllib.request.urlopen(request)
  File "C:\Program Files\WindowsApps\PythonSoftwareFoundation.Python.3.10_3.10.2032.0_x64__qbz5n2kfra8p0\lib\urllib\request.py", line 216, in urlopen
    return opener.open(url, data, timeout)
  File "C:\Program Files\WindowsApps\PythonSoftwareFoundation.Python.3.10_3.10.2032.0_x64__qbz5n2kfra8p0\lib\urllib\request.py", line 519, in open
    response = self._open(req, data)
  File "C:\Program Files\WindowsApps\PythonSoftwareFoundation.Python.3.10_3.10.2032.0_x64__qbz5n2kfra8p0\lib\urllib\request.py", line 536, in _open
    result = self._call_chain(self.handle_open, protocol, protocol +
  File "C:\Program Files\WindowsApps\PythonSoftwareFoundation.Python.3.10_3.10.2032.0_x64__qbz5n2kfra8p0\lib\urllib\request.py", line 496, in _call_chain
    result = func(*args)
  File "C:\Program Files\WindowsApps\PythonSoftwareFoundation.Python.3.10_3.10.2032.0_x64__qbz5n2kfra8p0\lib\urllib\request.py", line 1391, in https_open
    return self.do_open(http.client.HTTPSConnection, req,
  File "C:\Program Files\WindowsApps\PythonSoftwareFoundation.Python.3.10_3.10.2032.0_x64__qbz5n2kfra8p0\lib\urllib\request.py", line 1351, in do_open
    raise URLError(err)
urllib.error.URLError: <urlopen error [Errno 11001] getaddrinfo failed>
