  File "C:\Users\surma\Python\cfb_slapPY\sauce.py", line 10, in <module>
    quarters, name_dict = pbp_parser(url)
  File "C:\Users\surma\Python\cfb_slapPY\pbp_parser_func.py", line 14, in pbp_parser
    html = urlopen(url, context=ctx).read()
  File "C:\Program Files\WindowsApps\PythonSoftwareFoundation.Python.3.10_3.10.1776.0_x64__qbz5n2kfra8p0\lib\urllib\request.py", line 216, in urlopen
    return opener.open(url, data, timeout)
  File "C:\Program Files\WindowsApps\PythonSoftwareFoundation.Python.3.10_3.10.1776.0_x64__qbz5n2kfra8p0\lib\urllib\request.py", line 525, in open
    response = meth(req, response)
  File "C:\Program Files\WindowsApps\PythonSoftwareFoundation.Python.3.10_3.10.1776.0_x64__qbz5n2kfra8p0\lib\urllib\request.py", line 634, in http_response
    response = self.parent.error(
  File "C:\Program Files\WindowsApps\PythonSoftwareFoundation.Python.3.10_3.10.1776.0_x64__qbz5n2kfra8p0\lib\urllib\request.py", line 557, in error
    result = self._call_chain(*args)
  File "C:\Program Files\WindowsApps\PythonSoftwareFoundation.Python.3.10_3.10.1776.0_x64__qbz5n2kfra8p0\lib\urllib\request.py", line 496, in _call_chain
    result = func(*args)
  File "C:\Program Files\WindowsApps\PythonSoftwareFoundation.Python.3.10_3.10.1776.0_x64__qbz5n2kfra8p0\lib\urllib\request.py", line 749, in http_error_302
    return self.parent.open(new, timeout=req.timeout)
  File "C:\Program Files\WindowsApps\PythonSoftwareFoundation.Python.3.10_3.10.1776.0_x64__qbz5n2kfra8p0\lib\urllib\request.py", line 525, in open
    response = meth(req, response)
  File "C:\Program Files\WindowsApps\PythonSoftwareFoundation.Python.3.10_3.10.1776.0_x64__qbz5n2kfra8p0\lib\urllib\request.py", line 634, in http_response
    response = self.parent.error(
  File "C:\Program Files\WindowsApps\PythonSoftwareFoundation.Python.3.10_3.10.1776.0_x64__qbz5n2kfra8p0\lib\urllib\request.py", line 563, in error
    return self._call_chain(*args)
  File "C:\Program Files\WindowsApps\PythonSoftwareFoundation.Python.3.10_3.10.1776.0_x64__qbz5n2kfra8p0\lib\urllib\request.py", line 496, in _call_chain
    result = func(*args)
  File "C:\Program Files\WindowsApps\PythonSoftwareFoundation.Python.3.10_3.10.1776.0_x64__qbz5n2kfra8p0\lib\urllib\request.py", line 643, in http_error_default
    raise HTTPError(req.full_url, code, msg, hdrs, fp)
    raise HTTPError(req.full_url, code, msg, hdrs, fp)
urllib.error.HTTPError: HTTP Error 403: Forbidden
Traceback (most recent call last):
  File "C:\Users\surma\Python\cfb_slapPY\sauce.py", line 13, in <module>
    quarters, name_dict = taster(url)  
  File "C:\Users\surma\Python\cfb_slapPY\taster_func.py", line 105, in taster
    abbr = abbr_finder(quarters[0][drive_count],abbr)
IndexError: list index out of range
  File "C:\Users\surma\Python\cfb_slapPY\sauce.py", line 10, in <module>
    quarters, name_dict = pbp_parser(url)
  File "C:\Users\surma\Python\cfb_slapPY\pbp_parser_func.py", line 14, in pbp_parser
    html = urlopen(url, context=ctx).read()
  File "C:\Program Files\WindowsApps\PythonSoftwareFoundation.Python.3.10_3.10.1776.0_x64__qbz5n2kfra8p0\lib\urllib\request.py", line 216, in urlopen
    return opener.open(url, data, timeout)
  File "C:\Program Files\WindowsApps\PythonSoftwareFoundation.Python.3.10_3.10.1776.0_x64__qbz5n2kfra8p0\lib\urllib\request.py", line 525, in open
    response = meth(req, response)
  File "C:\Program Files\WindowsApps\PythonSoftwareFoundation.Python.3.10_3.10.1776.0_x64__qbz5n2kfra8p0\lib\urllib\request.py", line 634, in http_response
    response = self.parent.error(
  File "C:\Program Files\WindowsApps\PythonSoftwareFoundation.Python.3.10_3.10.1776.0_x64__qbz5n2kfra8p0\lib\urllib\request.py", line 557, in error
    result = self._call_chain(*args)
  File "C:\Program Files\WindowsApps\PythonSoftwareFoundation.Python.3.10_3.10.1776.0_x64__qbz5n2kfra8p0\lib\urllib\request.py", line 496, in _call_chain
    result = func(*args)
  File "C:\Program Files\WindowsApps\PythonSoftwareFoundation.Python.3.10_3.10.1776.0_x64__qbz5n2kfra8p0\lib\urllib\request.py", line 749, in http_error_302
    return self.parent.open(new, timeout=req.timeout)
  File "C:\Program Files\WindowsApps\PythonSoftwareFoundation.Python.3.10_3.10.1776.0_x64__qbz5n2kfra8p0\lib\urllib\request.py", line 525, in open
    response = meth(req, response)
  File "C:\Program Files\WindowsApps\PythonSoftwareFoundation.Python.3.10_3.10.1776.0_x64__qbz5n2kfra8p0\lib\urllib\request.py", line 634, in http_response
    response = self.parent.error(
  File "C:\Program Files\WindowsApps\PythonSoftwareFoundation.Python.3.10_3.10.1776.0_x64__qbz5n2kfra8p0\lib\urllib\request.py", line 563, in error
    return self._call_chain(*args)
  File "C:\Program Files\WindowsApps\PythonSoftwareFoundation.Python.3.10_3.10.1776.0_x64__qbz5n2kfra8p0\lib\urllib\request.py", line 496, in _call_chain
    result = func(*args)
  File "C:\Program Files\WindowsApps\PythonSoftwareFoundation.Python.3.10_3.10.1776.0_x64__qbz5n2kfra8p0\lib\urllib\request.py", line 643, in http_error_default
    raise HTTPError(req.full_url, code, msg, hdrs, fp)
    raise HTTPError(req.full_url, code, msg, hdrs, fp)
urllib.error.HTTPError: HTTP Error 403: Forbidden
Traceback (most recent call last):
  File "C:\Users\surma\Python\cfb_slapPY\sauce.py", line 13, in <module>
    quarters, name_dict = taster(url)  
  File "C:\Users\surma\Python\cfb_slapPY\taster_func.py", line 105, in taster
    abbr = abbr_finder(quarters[0][drive_count],abbr)
IndexError: list index out of range
  File "C:\Users\surma\Python\cfb_slapPY\sauce.py", line 10, in <module>
    quarters, name_dict = pbp_parser(url)
  File "C:\Users\surma\Python\cfb_slapPY\pbp_parser_func.py", line 14, in pbp_parser
    html = urlopen(url, context=ctx).read()
  File "C:\Program Files\WindowsApps\PythonSoftwareFoundation.Python.3.10_3.10.1776.0_x64__qbz5n2kfra8p0\lib\urllib\request.py", line 216, in urlopen
    return opener.open(url, data, timeout)
  File "C:\Program Files\WindowsApps\PythonSoftwareFoundation.Python.3.10_3.10.1776.0_x64__qbz5n2kfra8p0\lib\urllib\request.py", line 525, in open
    response = meth(req, response)
  File "C:\Program Files\WindowsApps\PythonSoftwareFoundation.Python.3.10_3.10.1776.0_x64__qbz5n2kfra8p0\lib\urllib\request.py", line 634, in http_response
    response = self.parent.error(
  File "C:\Program Files\WindowsApps\PythonSoftwareFoundation.Python.3.10_3.10.1776.0_x64__qbz5n2kfra8p0\lib\urllib\request.py", line 557, in error
    result = self._call_chain(*args)
  File "C:\Program Files\WindowsApps\PythonSoftwareFoundation.Python.3.10_3.10.1776.0_x64__qbz5n2kfra8p0\lib\urllib\request.py", line 496, in _call_chain
    result = func(*args)
  File "C:\Program Files\WindowsApps\PythonSoftwareFoundation.Python.3.10_3.10.1776.0_x64__qbz5n2kfra8p0\lib\urllib\request.py", line 749, in http_error_302
    return self.parent.open(new, timeout=req.timeout)
  File "C:\Program Files\WindowsApps\PythonSoftwareFoundation.Python.3.10_3.10.1776.0_x64__qbz5n2kfra8p0\lib\urllib\request.py", line 525, in open
    response = meth(req, response)
  File "C:\Program Files\WindowsApps\PythonSoftwareFoundation.Python.3.10_3.10.1776.0_x64__qbz5n2kfra8p0\lib\urllib\request.py", line 634, in http_response
    response = self.parent.error(
  File "C:\Program Files\WindowsApps\PythonSoftwareFoundation.Python.3.10_3.10.1776.0_x64__qbz5n2kfra8p0\lib\urllib\request.py", line 563, in error
    return self._call_chain(*args)
  File "C:\Program Files\WindowsApps\PythonSoftwareFoundation.Python.3.10_3.10.1776.0_x64__qbz5n2kfra8p0\lib\urllib\request.py", line 496, in _call_chain
    result = func(*args)
  File "C:\Program Files\WindowsApps\PythonSoftwareFoundation.Python.3.10_3.10.1776.0_x64__qbz5n2kfra8p0\lib\urllib\request.py", line 643, in http_error_default
    raise HTTPError(req.full_url, code, msg, hdrs, fp)
    raise HTTPError(req.full_url, code, msg, hdrs, fp)
urllib.error.HTTPError: HTTP Error 403: Forbidden
Traceback (most recent call last):
  File "C:\Users\surma\Python\cfb_slapPY\sauce.py", line 13, in <module>
    quarters, name_dict = taster(url)  
  File "C:\Users\surma\Python\cfb_slapPY\taster_func.py", line 105, in taster
    abbr = abbr_finder(quarters[0][drive_count],abbr)
IndexError: list index out of range
  File "C:\Users\surma\Python\cfb_slapPY\sauce.py", line 10, in <module>
    quarters, name_dict = pbp_parser(url)
  File "C:\Users\surma\Python\cfb_slapPY\pbp_parser_func.py", line 14, in pbp_parser
    html = urlopen(url, context=ctx).read()
  File "C:\Program Files\WindowsApps\PythonSoftwareFoundation.Python.3.10_3.10.1776.0_x64__qbz5n2kfra8p0\lib\urllib\request.py", line 216, in urlopen
    return opener.open(url, data, timeout)
  File "C:\Program Files\WindowsApps\PythonSoftwareFoundation.Python.3.10_3.10.1776.0_x64__qbz5n2kfra8p0\lib\urllib\request.py", line 525, in open
    response = meth(req, response)
  File "C:\Program Files\WindowsApps\PythonSoftwareFoundation.Python.3.10_3.10.1776.0_x64__qbz5n2kfra8p0\lib\urllib\request.py", line 634, in http_response
    response = self.parent.error(
  File "C:\Program Files\WindowsApps\PythonSoftwareFoundation.Python.3.10_3.10.1776.0_x64__qbz5n2kfra8p0\lib\urllib\request.py", line 557, in error
    result = self._call_chain(*args)
  File "C:\Program Files\WindowsApps\PythonSoftwareFoundation.Python.3.10_3.10.1776.0_x64__qbz5n2kfra8p0\lib\urllib\request.py", line 496, in _call_chain
    result = func(*args)
  File "C:\Program Files\WindowsApps\PythonSoftwareFoundation.Python.3.10_3.10.1776.0_x64__qbz5n2kfra8p0\lib\urllib\request.py", line 749, in http_error_302
    return self.parent.open(new, timeout=req.timeout)
  File "C:\Program Files\WindowsApps\PythonSoftwareFoundation.Python.3.10_3.10.1776.0_x64__qbz5n2kfra8p0\lib\urllib\request.py", line 525, in open
    response = meth(req, response)
  File "C:\Program Files\WindowsApps\PythonSoftwareFoundation.Python.3.10_3.10.1776.0_x64__qbz5n2kfra8p0\lib\urllib\request.py", line 634, in http_response
    response = self.parent.error(
  File "C:\Program Files\WindowsApps\PythonSoftwareFoundation.Python.3.10_3.10.1776.0_x64__qbz5n2kfra8p0\lib\urllib\request.py", line 563, in error
    return self._call_chain(*args)
  File "C:\Program Files\WindowsApps\PythonSoftwareFoundation.Python.3.10_3.10.1776.0_x64__qbz5n2kfra8p0\lib\urllib\request.py", line 496, in _call_chain
    result = func(*args)
  File "C:\Program Files\WindowsApps\PythonSoftwareFoundation.Python.3.10_3.10.1776.0_x64__qbz5n2kfra8p0\lib\urllib\request.py", line 643, in http_error_default
    raise HTTPError(req.full_url, code, msg, hdrs, fp)
    raise HTTPError(req.full_url, code, msg, hdrs, fp)
urllib.error.HTTPError: HTTP Error 403: Forbidden
Traceback (most recent call last):
  File "C:\Users\surma\Python\cfb_slapPY\sauce.py", line 13, in <module>
    quarters, name_dict = taster(url)  
  File "C:\Users\surma\Python\cfb_slapPY\taster_func.py", line 105, in taster
    abbr = abbr_finder(quarters[0][drive_count],abbr)
IndexError: list index out of range
  File "C:\Users\surma\Python\cfb_slapPY\sauce.py", line 10, in <module>
    quarters, name_dict = pbp_parser(url)
  File "C:\Users\surma\Python\cfb_slapPY\pbp_parser_func.py", line 14, in pbp_parser
    html = urlopen(url, context=ctx).read()
  File "C:\Program Files\WindowsApps\PythonSoftwareFoundation.Python.3.10_3.10.1776.0_x64__qbz5n2kfra8p0\lib\urllib\request.py", line 216, in urlopen
    return opener.open(url, data, timeout)
  File "C:\Program Files\WindowsApps\PythonSoftwareFoundation.Python.3.10_3.10.1776.0_x64__qbz5n2kfra8p0\lib\urllib\request.py", line 525, in open
    response = meth(req, response)
  File "C:\Program Files\WindowsApps\PythonSoftwareFoundation.Python.3.10_3.10.1776.0_x64__qbz5n2kfra8p0\lib\urllib\request.py", line 634, in http_response
    response = self.parent.error(
  File "C:\Program Files\WindowsApps\PythonSoftwareFoundation.Python.3.10_3.10.1776.0_x64__qbz5n2kfra8p0\lib\urllib\request.py", line 557, in error
    result = self._call_chain(*args)
  File "C:\Program Files\WindowsApps\PythonSoftwareFoundation.Python.3.10_3.10.1776.0_x64__qbz5n2kfra8p0\lib\urllib\request.py", line 496, in _call_chain
    result = func(*args)
  File "C:\Program Files\WindowsApps\PythonSoftwareFoundation.Python.3.10_3.10.1776.0_x64__qbz5n2kfra8p0\lib\urllib\request.py", line 749, in http_error_302
    return self.parent.open(new, timeout=req.timeout)
  File "C:\Program Files\WindowsApps\PythonSoftwareFoundation.Python.3.10_3.10.1776.0_x64__qbz5n2kfra8p0\lib\urllib\request.py", line 525, in open
    response = meth(req, response)
  File "C:\Program Files\WindowsApps\PythonSoftwareFoundation.Python.3.10_3.10.1776.0_x64__qbz5n2kfra8p0\lib\urllib\request.py", line 634, in http_response
    response = self.parent.error(
  File "C:\Program Files\WindowsApps\PythonSoftwareFoundation.Python.3.10_3.10.1776.0_x64__qbz5n2kfra8p0\lib\urllib\request.py", line 563, in error
    return self._call_chain(*args)
  File "C:\Program Files\WindowsApps\PythonSoftwareFoundation.Python.3.10_3.10.1776.0_x64__qbz5n2kfra8p0\lib\urllib\request.py", line 496, in _call_chain
    result = func(*args)
  File "C:\Program Files\WindowsApps\PythonSoftwareFoundation.Python.3.10_3.10.1776.0_x64__qbz5n2kfra8p0\lib\urllib\request.py", line 643, in http_error_default
    raise HTTPError(req.full_url, code, msg, hdrs, fp)
    raise HTTPError(req.full_url, code, msg, hdrs, fp)
urllib.error.HTTPError: HTTP Error 403: Forbidden
Traceback (most recent call last):
  File "C:\Users\surma\Python\cfb_slapPY\sauce.py", line 13, in <module>
    quarters, name_dict = taster(url)  
  File "C:\Users\surma\Python\cfb_slapPY\taster_func.py", line 105, in taster
    abbr = abbr_finder(quarters[0][drive_count],abbr)
IndexError: list index out of range
  File "C:\Users\surma\Python\cfb_slapPY\sauce.py", line 10, in <module>
    quarters, name_dict = pbp_parser(url)
  File "C:\Users\surma\Python\cfb_slapPY\pbp_parser_func.py", line 14, in pbp_parser
    html = urlopen(url, context=ctx).read()
  File "C:\Program Files\WindowsApps\PythonSoftwareFoundation.Python.3.10_3.10.1776.0_x64__qbz5n2kfra8p0\lib\urllib\request.py", line 216, in urlopen
    return opener.open(url, data, timeout)
  File "C:\Program Files\WindowsApps\PythonSoftwareFoundation.Python.3.10_3.10.1776.0_x64__qbz5n2kfra8p0\lib\urllib\request.py", line 525, in open
    response = meth(req, response)
  File "C:\Program Files\WindowsApps\PythonSoftwareFoundation.Python.3.10_3.10.1776.0_x64__qbz5n2kfra8p0\lib\urllib\request.py", line 634, in http_response
    response = self.parent.error(
  File "C:\Program Files\WindowsApps\PythonSoftwareFoundation.Python.3.10_3.10.1776.0_x64__qbz5n2kfra8p0\lib\urllib\request.py", line 557, in error
    result = self._call_chain(*args)
  File "C:\Program Files\WindowsApps\PythonSoftwareFoundation.Python.3.10_3.10.1776.0_x64__qbz5n2kfra8p0\lib\urllib\request.py", line 496, in _call_chain
    result = func(*args)
  File "C:\Program Files\WindowsApps\PythonSoftwareFoundation.Python.3.10_3.10.1776.0_x64__qbz5n2kfra8p0\lib\urllib\request.py", line 749, in http_error_302
    return self.parent.open(new, timeout=req.timeout)
  File "C:\Program Files\WindowsApps\PythonSoftwareFoundation.Python.3.10_3.10.1776.0_x64__qbz5n2kfra8p0\lib\urllib\request.py", line 525, in open
    response = meth(req, response)
  File "C:\Program Files\WindowsApps\PythonSoftwareFoundation.Python.3.10_3.10.1776.0_x64__qbz5n2kfra8p0\lib\urllib\request.py", line 634, in http_response
    response = self.parent.error(
  File "C:\Program Files\WindowsApps\PythonSoftwareFoundation.Python.3.10_3.10.1776.0_x64__qbz5n2kfra8p0\lib\urllib\request.py", line 563, in error
    return self._call_chain(*args)
  File "C:\Program Files\WindowsApps\PythonSoftwareFoundation.Python.3.10_3.10.1776.0_x64__qbz5n2kfra8p0\lib\urllib\request.py", line 496, in _call_chain
    result = func(*args)
  File "C:\Program Files\WindowsApps\PythonSoftwareFoundation.Python.3.10_3.10.1776.0_x64__qbz5n2kfra8p0\lib\urllib\request.py", line 643, in http_error_default
    raise HTTPError(req.full_url, code, msg, hdrs, fp)
    raise HTTPError(req.full_url, code, msg, hdrs, fp)
urllib.error.HTTPError: HTTP Error 403: Forbidden
Traceback (most recent call last):
  File "C:\Users\surma\Python\cfb_slapPY\sauce.py", line 13, in <module>
    quarters, name_dict = taster(url)  
  File "C:\Users\surma\Python\cfb_slapPY\taster_func.py", line 105, in taster
    abbr = abbr_finder(quarters[0][drive_count],abbr)
IndexError: list index out of range
  File "C:\Users\surma\Python\cfb_slapPY\sauce.py", line 10, in <module>
    quarters, name_dict = pbp_parser(url)
  File "C:\Users\surma\Python\cfb_slapPY\pbp_parser_func.py", line 14, in pbp_parser
    html = urlopen(url, context=ctx).read()
  File "C:\Program Files\WindowsApps\PythonSoftwareFoundation.Python.3.10_3.10.1776.0_x64__qbz5n2kfra8p0\lib\urllib\request.py", line 216, in urlopen
    return opener.open(url, data, timeout)
  File "C:\Program Files\WindowsApps\PythonSoftwareFoundation.Python.3.10_3.10.1776.0_x64__qbz5n2kfra8p0\lib\urllib\request.py", line 525, in open
    response = meth(req, response)
  File "C:\Program Files\WindowsApps\PythonSoftwareFoundation.Python.3.10_3.10.1776.0_x64__qbz5n2kfra8p0\lib\urllib\request.py", line 634, in http_response
    response = self.parent.error(
  File "C:\Program Files\WindowsApps\PythonSoftwareFoundation.Python.3.10_3.10.1776.0_x64__qbz5n2kfra8p0\lib\urllib\request.py", line 557, in error
    result = self._call_chain(*args)
  File "C:\Program Files\WindowsApps\PythonSoftwareFoundation.Python.3.10_3.10.1776.0_x64__qbz5n2kfra8p0\lib\urllib\request.py", line 496, in _call_chain
    result = func(*args)
  File "C:\Program Files\WindowsApps\PythonSoftwareFoundation.Python.3.10_3.10.1776.0_x64__qbz5n2kfra8p0\lib\urllib\request.py", line 749, in http_error_302
    return self.parent.open(new, timeout=req.timeout)
  File "C:\Program Files\WindowsApps\PythonSoftwareFoundation.Python.3.10_3.10.1776.0_x64__qbz5n2kfra8p0\lib\urllib\request.py", line 525, in open
    response = meth(req, response)
  File "C:\Program Files\WindowsApps\PythonSoftwareFoundation.Python.3.10_3.10.1776.0_x64__qbz5n2kfra8p0\lib\urllib\request.py", line 634, in http_response
    response = self.parent.error(
  File "C:\Program Files\WindowsApps\PythonSoftwareFoundation.Python.3.10_3.10.1776.0_x64__qbz5n2kfra8p0\lib\urllib\request.py", line 563, in error
    return self._call_chain(*args)
  File "C:\Program Files\WindowsApps\PythonSoftwareFoundation.Python.3.10_3.10.1776.0_x64__qbz5n2kfra8p0\lib\urllib\request.py", line 496, in _call_chain
    result = func(*args)
  File "C:\Program Files\WindowsApps\PythonSoftwareFoundation.Python.3.10_3.10.1776.0_x64__qbz5n2kfra8p0\lib\urllib\request.py", line 643, in http_error_default
    raise HTTPError(req.full_url, code, msg, hdrs, fp)
    raise HTTPError(req.full_url, code, msg, hdrs, fp)
urllib.error.HTTPError: HTTP Error 403: Forbidden
Traceback (most recent call last):
  File "C:\Users\surma\Python\cfb_slapPY\sauce.py", line 13, in <module>
    quarters, name_dict = taster(url)  
  File "C:\Users\surma\Python\cfb_slapPY\taster_func.py", line 105, in taster
    abbr = abbr_finder(quarters[0][drive_count],abbr)
IndexError: list index out of range
  File "C:\Users\surma\Python\cfb_slapPY\sauce.py", line 10, in <module>
    quarters, name_dict = pbp_parser(url)
  File "C:\Users\surma\Python\cfb_slapPY\pbp_parser_func.py", line 14, in pbp_parser
    html = urlopen(url, context=ctx).read()
  File "C:\Program Files\WindowsApps\PythonSoftwareFoundation.Python.3.10_3.10.1776.0_x64__qbz5n2kfra8p0\lib\urllib\request.py", line 216, in urlopen
    return opener.open(url, data, timeout)
  File "C:\Program Files\WindowsApps\PythonSoftwareFoundation.Python.3.10_3.10.1776.0_x64__qbz5n2kfra8p0\lib\urllib\request.py", line 525, in open
    response = meth(req, response)
  File "C:\Program Files\WindowsApps\PythonSoftwareFoundation.Python.3.10_3.10.1776.0_x64__qbz5n2kfra8p0\lib\urllib\request.py", line 634, in http_response
    response = self.parent.error(
  File "C:\Program Files\WindowsApps\PythonSoftwareFoundation.Python.3.10_3.10.1776.0_x64__qbz5n2kfra8p0\lib\urllib\request.py", line 557, in error
    result = self._call_chain(*args)
  File "C:\Program Files\WindowsApps\PythonSoftwareFoundation.Python.3.10_3.10.1776.0_x64__qbz5n2kfra8p0\lib\urllib\request.py", line 496, in _call_chain
    result = func(*args)
  File "C:\Program Files\WindowsApps\PythonSoftwareFoundation.Python.3.10_3.10.1776.0_x64__qbz5n2kfra8p0\lib\urllib\request.py", line 749, in http_error_302
    return self.parent.open(new, timeout=req.timeout)
  File "C:\Program Files\WindowsApps\PythonSoftwareFoundation.Python.3.10_3.10.1776.0_x64__qbz5n2kfra8p0\lib\urllib\request.py", line 525, in open
    response = meth(req, response)
  File "C:\Program Files\WindowsApps\PythonSoftwareFoundation.Python.3.10_3.10.1776.0_x64__qbz5n2kfra8p0\lib\urllib\request.py", line 634, in http_response
    response = self.parent.error(
  File "C:\Program Files\WindowsApps\PythonSoftwareFoundation.Python.3.10_3.10.1776.0_x64__qbz5n2kfra8p0\lib\urllib\request.py", line 563, in error
    return self._call_chain(*args)
  File "C:\Program Files\WindowsApps\PythonSoftwareFoundation.Python.3.10_3.10.1776.0_x64__qbz5n2kfra8p0\lib\urllib\request.py", line 496, in _call_chain
    result = func(*args)
  File "C:\Program Files\WindowsApps\PythonSoftwareFoundation.Python.3.10_3.10.1776.0_x64__qbz5n2kfra8p0\lib\urllib\request.py", line 643, in http_error_default
    raise HTTPError(req.full_url, code, msg, hdrs, fp)
    raise HTTPError(req.full_url, code, msg, hdrs, fp)
urllib.error.HTTPError: HTTP Error 403: Forbidden
Traceback (most recent call last):
  File "C:\Users\surma\Python\cfb_slapPY\sauce.py", line 13, in <module>
    quarters, name_dict = taster(url)  
  File "C:\Users\surma\Python\cfb_slapPY\taster_func.py", line 105, in taster
    abbr = abbr_finder(quarters[0][drive_count],abbr)
IndexError: list index out of range
  File "C:\Users\surma\Python\cfb_slapPY\sauce.py", line 10, in <module>
    quarters, name_dict = pbp_parser(url)
  File "C:\Users\surma\Python\cfb_slapPY\pbp_parser_func.py", line 14, in pbp_parser
    html = urlopen(url, context=ctx).read()
  File "C:\Program Files\WindowsApps\PythonSoftwareFoundation.Python.3.10_3.10.1776.0_x64__qbz5n2kfra8p0\lib\urllib\request.py", line 216, in urlopen
    return opener.open(url, data, timeout)
  File "C:\Program Files\WindowsApps\PythonSoftwareFoundation.Python.3.10_3.10.1776.0_x64__qbz5n2kfra8p0\lib\urllib\request.py", line 525, in open
    response = meth(req, response)
  File "C:\Program Files\WindowsApps\PythonSoftwareFoundation.Python.3.10_3.10.1776.0_x64__qbz5n2kfra8p0\lib\urllib\request.py", line 634, in http_response
    response = self.parent.error(
  File "C:\Program Files\WindowsApps\PythonSoftwareFoundation.Python.3.10_3.10.1776.0_x64__qbz5n2kfra8p0\lib\urllib\request.py", line 557, in error
    result = self._call_chain(*args)
  File "C:\Program Files\WindowsApps\PythonSoftwareFoundation.Python.3.10_3.10.1776.0_x64__qbz5n2kfra8p0\lib\urllib\request.py", line 496, in _call_chain
    result = func(*args)
  File "C:\Program Files\WindowsApps\PythonSoftwareFoundation.Python.3.10_3.10.1776.0_x64__qbz5n2kfra8p0\lib\urllib\request.py", line 749, in http_error_302
    return self.parent.open(new, timeout=req.timeout)
  File "C:\Program Files\WindowsApps\PythonSoftwareFoundation.Python.3.10_3.10.1776.0_x64__qbz5n2kfra8p0\lib\urllib\request.py", line 525, in open
    response = meth(req, response)
  File "C:\Program Files\WindowsApps\PythonSoftwareFoundation.Python.3.10_3.10.1776.0_x64__qbz5n2kfra8p0\lib\urllib\request.py", line 634, in http_response
    response = self.parent.error(
  File "C:\Program Files\WindowsApps\PythonSoftwareFoundation.Python.3.10_3.10.1776.0_x64__qbz5n2kfra8p0\lib\urllib\request.py", line 563, in error
    return self._call_chain(*args)
  File "C:\Program Files\WindowsApps\PythonSoftwareFoundation.Python.3.10_3.10.1776.0_x64__qbz5n2kfra8p0\lib\urllib\request.py", line 496, in _call_chain
    result = func(*args)
  File "C:\Program Files\WindowsApps\PythonSoftwareFoundation.Python.3.10_3.10.1776.0_x64__qbz5n2kfra8p0\lib\urllib\request.py", line 643, in http_error_default
    raise HTTPError(req.full_url, code, msg, hdrs, fp)
    raise HTTPError(req.full_url, code, msg, hdrs, fp)
urllib.error.HTTPError: HTTP Error 403: Forbidden
Traceback (most recent call last):
  File "C:\Users\surma\Python\cfb_slapPY\sauce.py", line 13, in <module>
    quarters, name_dict = taster(url)  
  File "C:\Users\surma\Python\cfb_slapPY\taster_func.py", line 105, in taster
    abbr = abbr_finder(quarters[0][drive_count],abbr)
IndexError: list index out of range
  File "C:\Users\surma\Python\cfb_slapPY\sauce.py", line 10, in <module>
    quarters, name_dict = pbp_parser(url)
  File "C:\Users\surma\Python\cfb_slapPY\pbp_parser_func.py", line 14, in pbp_parser
    html = urlopen(url, context=ctx).read()
  File "C:\Program Files\WindowsApps\PythonSoftwareFoundation.Python.3.10_3.10.1776.0_x64__qbz5n2kfra8p0\lib\urllib\request.py", line 216, in urlopen
    return opener.open(url, data, timeout)
  File "C:\Program Files\WindowsApps\PythonSoftwareFoundation.Python.3.10_3.10.1776.0_x64__qbz5n2kfra8p0\lib\urllib\request.py", line 525, in open
    response = meth(req, response)
  File "C:\Program Files\WindowsApps\PythonSoftwareFoundation.Python.3.10_3.10.1776.0_x64__qbz5n2kfra8p0\lib\urllib\request.py", line 634, in http_response
    response = self.parent.error(
  File "C:\Program Files\WindowsApps\PythonSoftwareFoundation.Python.3.10_3.10.1776.0_x64__qbz5n2kfra8p0\lib\urllib\request.py", line 557, in error
    result = self._call_chain(*args)
  File "C:\Program Files\WindowsApps\PythonSoftwareFoundation.Python.3.10_3.10.1776.0_x64__qbz5n2kfra8p0\lib\urllib\request.py", line 496, in _call_chain
    result = func(*args)
  File "C:\Program Files\WindowsApps\PythonSoftwareFoundation.Python.3.10_3.10.1776.0_x64__qbz5n2kfra8p0\lib\urllib\request.py", line 749, in http_error_302
    return self.parent.open(new, timeout=req.timeout)
  File "C:\Program Files\WindowsApps\PythonSoftwareFoundation.Python.3.10_3.10.1776.0_x64__qbz5n2kfra8p0\lib\urllib\request.py", line 525, in open
    response = meth(req, response)
  File "C:\Program Files\WindowsApps\PythonSoftwareFoundation.Python.3.10_3.10.1776.0_x64__qbz5n2kfra8p0\lib\urllib\request.py", line 634, in http_response
    response = self.parent.error(
  File "C:\Program Files\WindowsApps\PythonSoftwareFoundation.Python.3.10_3.10.1776.0_x64__qbz5n2kfra8p0\lib\urllib\request.py", line 563, in error
    return self._call_chain(*args)
  File "C:\Program Files\WindowsApps\PythonSoftwareFoundation.Python.3.10_3.10.1776.0_x64__qbz5n2kfra8p0\lib\urllib\request.py", line 496, in _call_chain
    result = func(*args)
  File "C:\Program Files\WindowsApps\PythonSoftwareFoundation.Python.3.10_3.10.1776.0_x64__qbz5n2kfra8p0\lib\urllib\request.py", line 643, in http_error_default
    raise HTTPError(req.full_url, code, msg, hdrs, fp)
    raise HTTPError(req.full_url, code, msg, hdrs, fp)
urllib.error.HTTPError: HTTP Error 403: Forbidden
Traceback (most recent call last):
  File "C:\Users\surma\Python\cfb_slapPY\sauce.py", line 13, in <module>
    quarters, name_dict = taster(url)  
  File "C:\Users\surma\Python\cfb_slapPY\taster_func.py", line 105, in taster
    abbr = abbr_finder(quarters[0][drive_count],abbr)
IndexError: list index out of range
  File "C:\Users\surma\Python\cfb_slapPY\sauce.py", line 10, in <module>
    quarters, name_dict = pbp_parser(url)
  File "C:\Users\surma\Python\cfb_slapPY\pbp_parser_func.py", line 14, in pbp_parser
    html = urlopen(url, context=ctx).read()
  File "C:\Program Files\WindowsApps\PythonSoftwareFoundation.Python.3.10_3.10.1776.0_x64__qbz5n2kfra8p0\lib\urllib\request.py", line 216, in urlopen
    return opener.open(url, data, timeout)
  File "C:\Program Files\WindowsApps\PythonSoftwareFoundation.Python.3.10_3.10.1776.0_x64__qbz5n2kfra8p0\lib\urllib\request.py", line 525, in open
    response = meth(req, response)
  File "C:\Program Files\WindowsApps\PythonSoftwareFoundation.Python.3.10_3.10.1776.0_x64__qbz5n2kfra8p0\lib\urllib\request.py", line 634, in http_response
    response = self.parent.error(
  File "C:\Program Files\WindowsApps\PythonSoftwareFoundation.Python.3.10_3.10.1776.0_x64__qbz5n2kfra8p0\lib\urllib\request.py", line 557, in error
    result = self._call_chain(*args)
  File "C:\Program Files\WindowsApps\PythonSoftwareFoundation.Python.3.10_3.10.1776.0_x64__qbz5n2kfra8p0\lib\urllib\request.py", line 496, in _call_chain
    result = func(*args)
  File "C:\Program Files\WindowsApps\PythonSoftwareFoundation.Python.3.10_3.10.1776.0_x64__qbz5n2kfra8p0\lib\urllib\request.py", line 749, in http_error_302
    return self.parent.open(new, timeout=req.timeout)
  File "C:\Program Files\WindowsApps\PythonSoftwareFoundation.Python.3.10_3.10.1776.0_x64__qbz5n2kfra8p0\lib\urllib\request.py", line 525, in open
    response = meth(req, response)
  File "C:\Program Files\WindowsApps\PythonSoftwareFoundation.Python.3.10_3.10.1776.0_x64__qbz5n2kfra8p0\lib\urllib\request.py", line 634, in http_response
    response = self.parent.error(
  File "C:\Program Files\WindowsApps\PythonSoftwareFoundation.Python.3.10_3.10.1776.0_x64__qbz5n2kfra8p0\lib\urllib\request.py", line 563, in error
    return self._call_chain(*args)
  File "C:\Program Files\WindowsApps\PythonSoftwareFoundation.Python.3.10_3.10.1776.0_x64__qbz5n2kfra8p0\lib\urllib\request.py", line 496, in _call_chain
    result = func(*args)
  File "C:\Program Files\WindowsApps\PythonSoftwareFoundation.Python.3.10_3.10.1776.0_x64__qbz5n2kfra8p0\lib\urllib\request.py", line 643, in http_error_default
    raise HTTPError(req.full_url, code, msg, hdrs, fp)
    raise HTTPError(req.full_url, code, msg, hdrs, fp)
urllib.error.HTTPError: HTTP Error 403: Forbidden
Traceback (most recent call last):
  File "C:\Users\surma\Python\cfb_slapPY\sauce.py", line 13, in <module>
    quarters, name_dict = taster(url)  
  File "C:\Users\surma\Python\cfb_slapPY\taster_func.py", line 25, in taster
    name_dict[away_name] = team_names[0].string
IndexError: list index out of range
  File "C:\Users\surma\Python\cfb_slapPY\sauce.py", line 10, in <module>
    quarters, name_dict = pbp_parser(url)
  File "C:\Users\surma\Python\cfb_slapPY\pbp_parser_func.py", line 14, in pbp_parser
    html = urlopen(url, context=ctx).read()
  File "C:\Program Files\WindowsApps\PythonSoftwareFoundation.Python.3.10_3.10.1776.0_x64__qbz5n2kfra8p0\lib\urllib\request.py", line 216, in urlopen
    return opener.open(url, data, timeout)
  File "C:\Program Files\WindowsApps\PythonSoftwareFoundation.Python.3.10_3.10.1776.0_x64__qbz5n2kfra8p0\lib\urllib\request.py", line 525, in open
    response = meth(req, response)
  File "C:\Program Files\WindowsApps\PythonSoftwareFoundation.Python.3.10_3.10.1776.0_x64__qbz5n2kfra8p0\lib\urllib\request.py", line 634, in http_response
    response = self.parent.error(
  File "C:\Program Files\WindowsApps\PythonSoftwareFoundation.Python.3.10_3.10.1776.0_x64__qbz5n2kfra8p0\lib\urllib\request.py", line 557, in error
    result = self._call_chain(*args)
  File "C:\Program Files\WindowsApps\PythonSoftwareFoundation.Python.3.10_3.10.1776.0_x64__qbz5n2kfra8p0\lib\urllib\request.py", line 496, in _call_chain
    result = func(*args)
  File "C:\Program Files\WindowsApps\PythonSoftwareFoundation.Python.3.10_3.10.1776.0_x64__qbz5n2kfra8p0\lib\urllib\request.py", line 749, in http_error_302
    return self.parent.open(new, timeout=req.timeout)
  File "C:\Program Files\WindowsApps\PythonSoftwareFoundation.Python.3.10_3.10.1776.0_x64__qbz5n2kfra8p0\lib\urllib\request.py", line 525, in open
    response = meth(req, response)
  File "C:\Program Files\WindowsApps\PythonSoftwareFoundation.Python.3.10_3.10.1776.0_x64__qbz5n2kfra8p0\lib\urllib\request.py", line 634, in http_response
    response = self.parent.error(
  File "C:\Program Files\WindowsApps\PythonSoftwareFoundation.Python.3.10_3.10.1776.0_x64__qbz5n2kfra8p0\lib\urllib\request.py", line 563, in error
    return self._call_chain(*args)
  File "C:\Program Files\WindowsApps\PythonSoftwareFoundation.Python.3.10_3.10.1776.0_x64__qbz5n2kfra8p0\lib\urllib\request.py", line 496, in _call_chain
    result = func(*args)
  File "C:\Program Files\WindowsApps\PythonSoftwareFoundation.Python.3.10_3.10.1776.0_x64__qbz5n2kfra8p0\lib\urllib\request.py", line 643, in http_error_default
    raise HTTPError(req.full_url, code, msg, hdrs, fp)
    raise HTTPError(req.full_url, code, msg, hdrs, fp)
urllib.error.HTTPError: HTTP Error 403: Forbidden
Traceback (most recent call last):
  File "C:\Users\surma\Python\cfb_slapPY\sauce.py", line 13, in <module>
    quarters, name_dict = taster(url)  
  File "C:\Users\surma\Python\cfb_slapPY\taster_func.py", line 25, in taster
    name_dict[away_name] = team_names[0].string
IndexError: list index out of range
  File "C:\Users\surma\Python\cfb_slapPY\sauce.py", line 10, in <module>
    quarters, name_dict = pbp_parser(url)
  File "C:\Users\surma\Python\cfb_slapPY\pbp_parser_func.py", line 14, in pbp_parser
    html = urlopen(url, context=ctx).read()
  File "C:\Program Files\WindowsApps\PythonSoftwareFoundation.Python.3.10_3.10.1776.0_x64__qbz5n2kfra8p0\lib\urllib\request.py", line 216, in urlopen
    return opener.open(url, data, timeout)
  File "C:\Program Files\WindowsApps\PythonSoftwareFoundation.Python.3.10_3.10.1776.0_x64__qbz5n2kfra8p0\lib\urllib\request.py", line 525, in open
    response = meth(req, response)
  File "C:\Program Files\WindowsApps\PythonSoftwareFoundation.Python.3.10_3.10.1776.0_x64__qbz5n2kfra8p0\lib\urllib\request.py", line 634, in http_response
    response = self.parent.error(
  File "C:\Program Files\WindowsApps\PythonSoftwareFoundation.Python.3.10_3.10.1776.0_x64__qbz5n2kfra8p0\lib\urllib\request.py", line 557, in error
    result = self._call_chain(*args)
  File "C:\Program Files\WindowsApps\PythonSoftwareFoundation.Python.3.10_3.10.1776.0_x64__qbz5n2kfra8p0\lib\urllib\request.py", line 496, in _call_chain
    result = func(*args)
  File "C:\Program Files\WindowsApps\PythonSoftwareFoundation.Python.3.10_3.10.1776.0_x64__qbz5n2kfra8p0\lib\urllib\request.py", line 749, in http_error_302
    return self.parent.open(new, timeout=req.timeout)
  File "C:\Program Files\WindowsApps\PythonSoftwareFoundation.Python.3.10_3.10.1776.0_x64__qbz5n2kfra8p0\lib\urllib\request.py", line 525, in open
    response = meth(req, response)
  File "C:\Program Files\WindowsApps\PythonSoftwareFoundation.Python.3.10_3.10.1776.0_x64__qbz5n2kfra8p0\lib\urllib\request.py", line 634, in http_response
    response = self.parent.error(
  File "C:\Program Files\WindowsApps\PythonSoftwareFoundation.Python.3.10_3.10.1776.0_x64__qbz5n2kfra8p0\lib\urllib\request.py", line 563, in error
    return self._call_chain(*args)
  File "C:\Program Files\WindowsApps\PythonSoftwareFoundation.Python.3.10_3.10.1776.0_x64__qbz5n2kfra8p0\lib\urllib\request.py", line 496, in _call_chain
    result = func(*args)
  File "C:\Program Files\WindowsApps\PythonSoftwareFoundation.Python.3.10_3.10.1776.0_x64__qbz5n2kfra8p0\lib\urllib\request.py", line 643, in http_error_default
    raise HTTPError(req.full_url, code, msg, hdrs, fp)
    raise HTTPError(req.full_url, code, msg, hdrs, fp)
urllib.error.HTTPError: HTTP Error 403: Forbidden
Traceback (most recent call last):
  File "C:\Users\surma\Python\cfb_slapPY\sauce.py", line 13, in <module>
    quarters, name_dict = taster(url)  
  File "C:\Users\surma\Python\cfb_slapPY\taster_func.py", line 25, in taster
    name_dict[away_name] = team_names[0].string
IndexError: list index out of range
  File "C:\Users\surma\Python\cfb_slapPY\sauce.py", line 10, in <module>
    quarters, name_dict = pbp_parser(url)
  File "C:\Users\surma\Python\cfb_slapPY\pbp_parser_func.py", line 14, in pbp_parser
    html = urlopen(url, context=ctx).read()
  File "C:\Program Files\WindowsApps\PythonSoftwareFoundation.Python.3.10_3.10.1776.0_x64__qbz5n2kfra8p0\lib\urllib\request.py", line 216, in urlopen
    return opener.open(url, data, timeout)
  File "C:\Program Files\WindowsApps\PythonSoftwareFoundation.Python.3.10_3.10.1776.0_x64__qbz5n2kfra8p0\lib\urllib\request.py", line 525, in open
    response = meth(req, response)
  File "C:\Program Files\WindowsApps\PythonSoftwareFoundation.Python.3.10_3.10.1776.0_x64__qbz5n2kfra8p0\lib\urllib\request.py", line 634, in http_response
    response = self.parent.error(
  File "C:\Program Files\WindowsApps\PythonSoftwareFoundation.Python.3.10_3.10.1776.0_x64__qbz5n2kfra8p0\lib\urllib\request.py", line 557, in error
    result = self._call_chain(*args)
  File "C:\Program Files\WindowsApps\PythonSoftwareFoundation.Python.3.10_3.10.1776.0_x64__qbz5n2kfra8p0\lib\urllib\request.py", line 496, in _call_chain
    result = func(*args)
  File "C:\Program Files\WindowsApps\PythonSoftwareFoundation.Python.3.10_3.10.1776.0_x64__qbz5n2kfra8p0\lib\urllib\request.py", line 749, in http_error_302
    return self.parent.open(new, timeout=req.timeout)
  File "C:\Program Files\WindowsApps\PythonSoftwareFoundation.Python.3.10_3.10.1776.0_x64__qbz5n2kfra8p0\lib\urllib\request.py", line 525, in open
    response = meth(req, response)
  File "C:\Program Files\WindowsApps\PythonSoftwareFoundation.Python.3.10_3.10.1776.0_x64__qbz5n2kfra8p0\lib\urllib\request.py", line 634, in http_response
    response = self.parent.error(
  File "C:\Program Files\WindowsApps\PythonSoftwareFoundation.Python.3.10_3.10.1776.0_x64__qbz5n2kfra8p0\lib\urllib\request.py", line 563, in error
    return self._call_chain(*args)
  File "C:\Program Files\WindowsApps\PythonSoftwareFoundation.Python.3.10_3.10.1776.0_x64__qbz5n2kfra8p0\lib\urllib\request.py", line 496, in _call_chain
    result = func(*args)
  File "C:\Program Files\WindowsApps\PythonSoftwareFoundation.Python.3.10_3.10.1776.0_x64__qbz5n2kfra8p0\lib\urllib\request.py", line 643, in http_error_default
    raise HTTPError(req.full_url, code, msg, hdrs, fp)
    raise HTTPError(req.full_url, code, msg, hdrs, fp)
urllib.error.HTTPError: HTTP Error 403: Forbidden
Traceback (most recent call last):
  File "C:\Users\surma\Python\cfb_slapPY\sauce.py", line 13, in <module>
    quarters, name_dict = taster(url)  
  File "C:\Users\surma\Python\cfb_slapPY\taster_func.py", line 25, in taster
    name_dict[away_name] = team_names[0].string
IndexError: list index out of range
  File "C:\Users\surma\Python\cfb_slapPY\sauce.py", line 10, in <module>
    quarters, name_dict = pbp_parser(url)
  File "C:\Users\surma\Python\cfb_slapPY\pbp_parser_func.py", line 14, in pbp_parser
    html = urlopen(url, context=ctx).read()
  File "C:\Program Files\WindowsApps\PythonSoftwareFoundation.Python.3.10_3.10.1776.0_x64__qbz5n2kfra8p0\lib\urllib\request.py", line 216, in urlopen
    return opener.open(url, data, timeout)
  File "C:\Program Files\WindowsApps\PythonSoftwareFoundation.Python.3.10_3.10.1776.0_x64__qbz5n2kfra8p0\lib\urllib\request.py", line 525, in open
    response = meth(req, response)
  File "C:\Program Files\WindowsApps\PythonSoftwareFoundation.Python.3.10_3.10.1776.0_x64__qbz5n2kfra8p0\lib\urllib\request.py", line 634, in http_response
    response = self.parent.error(
  File "C:\Program Files\WindowsApps\PythonSoftwareFoundation.Python.3.10_3.10.1776.0_x64__qbz5n2kfra8p0\lib\urllib\request.py", line 557, in error
    result = self._call_chain(*args)
  File "C:\Program Files\WindowsApps\PythonSoftwareFoundation.Python.3.10_3.10.1776.0_x64__qbz5n2kfra8p0\lib\urllib\request.py", line 496, in _call_chain
    result = func(*args)
  File "C:\Program Files\WindowsApps\PythonSoftwareFoundation.Python.3.10_3.10.1776.0_x64__qbz5n2kfra8p0\lib\urllib\request.py", line 749, in http_error_302
    return self.parent.open(new, timeout=req.timeout)
  File "C:\Program Files\WindowsApps\PythonSoftwareFoundation.Python.3.10_3.10.1776.0_x64__qbz5n2kfra8p0\lib\urllib\request.py", line 525, in open
    response = meth(req, response)
  File "C:\Program Files\WindowsApps\PythonSoftwareFoundation.Python.3.10_3.10.1776.0_x64__qbz5n2kfra8p0\lib\urllib\request.py", line 634, in http_response
    response = self.parent.error(
  File "C:\Program Files\WindowsApps\PythonSoftwareFoundation.Python.3.10_3.10.1776.0_x64__qbz5n2kfra8p0\lib\urllib\request.py", line 563, in error
    return self._call_chain(*args)
  File "C:\Program Files\WindowsApps\PythonSoftwareFoundation.Python.3.10_3.10.1776.0_x64__qbz5n2kfra8p0\lib\urllib\request.py", line 496, in _call_chain
    result = func(*args)
  File "C:\Program Files\WindowsApps\PythonSoftwareFoundation.Python.3.10_3.10.1776.0_x64__qbz5n2kfra8p0\lib\urllib\request.py", line 643, in http_error_default
    raise HTTPError(req.full_url, code, msg, hdrs, fp)
    raise HTTPError(req.full_url, code, msg, hdrs, fp)
urllib.error.HTTPError: HTTP Error 403: Forbidden
Traceback (most recent call last):
  File "C:\Users\surma\Python\cfb_slapPY\sauce.py", line 13, in <module>
    quarters, name_dict = taster(url)  
  File "C:\Users\surma\Python\cfb_slapPY\taster_func.py", line 25, in taster
    name_dict[away_name] = team_names[0].string
IndexError: list index out of range
  File "C:\Users\surma\Python\cfb_slapPY\sauce.py", line 10, in <module>
    quarters, name_dict = pbp_parser(url)
  File "C:\Users\surma\Python\cfb_slapPY\pbp_parser_func.py", line 14, in pbp_parser
    html = urlopen(url, context=ctx).read()
  File "C:\Program Files\WindowsApps\PythonSoftwareFoundation.Python.3.10_3.10.1776.0_x64__qbz5n2kfra8p0\lib\urllib\request.py", line 216, in urlopen
    return opener.open(url, data, timeout)
  File "C:\Program Files\WindowsApps\PythonSoftwareFoundation.Python.3.10_3.10.1776.0_x64__qbz5n2kfra8p0\lib\urllib\request.py", line 525, in open
    response = meth(req, response)
  File "C:\Program Files\WindowsApps\PythonSoftwareFoundation.Python.3.10_3.10.1776.0_x64__qbz5n2kfra8p0\lib\urllib\request.py", line 634, in http_response
    response = self.parent.error(
  File "C:\Program Files\WindowsApps\PythonSoftwareFoundation.Python.3.10_3.10.1776.0_x64__qbz5n2kfra8p0\lib\urllib\request.py", line 557, in error
    result = self._call_chain(*args)
  File "C:\Program Files\WindowsApps\PythonSoftwareFoundation.Python.3.10_3.10.1776.0_x64__qbz5n2kfra8p0\lib\urllib\request.py", line 496, in _call_chain
    result = func(*args)
  File "C:\Program Files\WindowsApps\PythonSoftwareFoundation.Python.3.10_3.10.1776.0_x64__qbz5n2kfra8p0\lib\urllib\request.py", line 749, in http_error_302
    return self.parent.open(new, timeout=req.timeout)
  File "C:\Program Files\WindowsApps\PythonSoftwareFoundation.Python.3.10_3.10.1776.0_x64__qbz5n2kfra8p0\lib\urllib\request.py", line 525, in open
    response = meth(req, response)
  File "C:\Program Files\WindowsApps\PythonSoftwareFoundation.Python.3.10_3.10.1776.0_x64__qbz5n2kfra8p0\lib\urllib\request.py", line 634, in http_response
    response = self.parent.error(
  File "C:\Program Files\WindowsApps\PythonSoftwareFoundation.Python.3.10_3.10.1776.0_x64__qbz5n2kfra8p0\lib\urllib\request.py", line 563, in error
    return self._call_chain(*args)
  File "C:\Program Files\WindowsApps\PythonSoftwareFoundation.Python.3.10_3.10.1776.0_x64__qbz5n2kfra8p0\lib\urllib\request.py", line 496, in _call_chain
    result = func(*args)
  File "C:\Program Files\WindowsApps\PythonSoftwareFoundation.Python.3.10_3.10.1776.0_x64__qbz5n2kfra8p0\lib\urllib\request.py", line 643, in http_error_default
    raise HTTPError(req.full_url, code, msg, hdrs, fp)
    raise HTTPError(req.full_url, code, msg, hdrs, fp)
urllib.error.HTTPError: HTTP Error 403: Forbidden
Traceback (most recent call last):
  File "C:\Users\surma\Python\cfb_slapPY\sauce.py", line 13, in <module>
    quarters, name_dict = taster(url)  
  File "C:\Users\surma\Python\cfb_slapPY\taster_func.py", line 25, in taster
    name_dict[away_name] = team_names[0].string
IndexError: list index out of range
